Workbook
Name Slicer_age_group: #N/A
Name Slicer_service: #N/A

Sheet staff
B1: staff_id | C1: staff_name | D1: role | E1: service
B2: STF-5ca26577 | C2: Allison Hill | D2: doctor | E2: emergency
B3: STF-02ae59ca | C3: Noah Rhodes | D3: doctor | E3: emergency
B4: STF-d8006e7c | C4: Angie Henderson | D4: doctor | E4: emergency
B5: STF-212d8b31 | C5: Daniel Wagner | D5: doctor | E5: emergency
B6: STF-107a58e4 | C6: Cristian Santos | D6: doctor | E6: emergency
B7: STF-ca932dea | C7: Connie Lawrence | D7: nurse | E7: emergency
B8: STF-39082289 | C8: Abigail Shaffer | D8: nurse | E8: emergency
B9: STF-702887af | C9: Gina Moore | D9: nurse | E9: emergency
B10: STF-249f63bb | C10: Gabrielle Davis | D10: nurse | E10: emergency
B11: STF-094f410b | C11: Ryan Munoz | D11: nurse | E11: emergency
B12: STF-d7ab0c23 | C12: Monica Herrera | D12: nurse | E12: emergency
... B111: STF-021fdf9f | C111: Sharon Cochran | D111: nursing_assistant | E111: ICU

Sheet services_weekly
B1: week | C1: month | D1: service | E1: available_beds | F1: patients_request | G1: patients_admitted | H1: patients_refused | I1: patient_satisfaction | J1: staff_morale | K1: event | L1: % of bed occupancy
B2: 1 | C2: 1 | D2: emergency | E2: 32 | F2: 76 | G2: 32 | H2: 44 | I2: 67 | J2: 70 | K2: none | L2: =services_weekly[[#This Row],[patients_admitted]]/services_weekly[[#This Row],[available_beds]] -> 1
B3: 1 | C3: 1 | D3: surgery | E3: 45 | F3: 130 | G3: 45 | H3: 85 | I3: 83 | J3: 78 | K3: flu | L3: =services_weekly[[#This Row],[patients_admitted]]/services_weekly[[#This Row],[available_beds]] -> 1
B4: 1 | C4: 1 | D4: general_medicine | E4: 37 | F4: 201 | G4: 37 | H4: 164 | I4: 97 | J4: 43 | K4: flu | L4: =services_weekly[[#This Row],[patients_admitted]]/services_weekly[[#This Row],[available_beds]] -> 1
B5: 1 | C5: 1 | D5: ICU | E5: 22 | F5: 31 | G5: 22 | H5: 9 | I5: 84 | J5: 91 | K5: flu | L5: =services_weekly[[#This Row],[patients_admitted]]/services_weekly[[#This Row],[available_beds]] -> 1
B6: 2 | C6: 1 | D6: emergency | E6: 28 | F6: 169 | G6: 28 | H6: 141 | I6: 75 | J6: 64 | K6: none | L6: =services_weekly[[#This Row],[patients_admitted]]/services_weekly[[#This Row],[available_beds]] -> 1
B7: 2 | C7: 1 | D7: surgery | E7: 40 | F7: 26 | G7: 26 | H7: 0 | I7: 96 | J7: 56 | K7: none | L7: =services_weekly[[#This Row],[patients_admitted]]/services_weekly[[#This Row],[available_beds]] -> 0.65
B8: 2 | C8: 1 | D8: general_medicine | E8: 43 | F8: 183 | G8: 43 | H8: 140 | I8: 73 | J8: 93 | K8: flu | L8: =services_weekly[[#This Row],[patients_admitted]]/services_weekly[[#This Row],[available_beds]] -> 1
B9: 2 | C9: 1 | D9: ICU | E9: 16 | F9: 7 | G9: 7 | H9: 0 | I9: 79 | J9: 85 | K9: donation | L9: =services_weekly[[#This Row],[patients_admitted]]/services_weekly[[#This Row],[available_beds]] -> 0.4375
B10: 3 | C10: 1 | D10: emergency | E10: 32 | F10: 177 | G10: 32 | H10: 145 | I10: 73 | J10: 58 | K10: flu | L10: =services_weekly[[#This Row],[patients_admitted]]/services_weekly[[#This Row],[available_beds]] -> 1
B11: 3 | C11: 1 | D11: surgery | E11: 27 | F11: 66 | G11: 27 | H11: 39 | I11: 63 | J11: 72 | K11: flu | L11: =services_weekly[[#This Row],[patients_admitted]]/services_weekly[[#This Row],[available_beds]] -> 1
B12: 3 | C12: 1 | D12: general_medicine | E12: 37 | F12: 58 | G12: 37 | H12: 21 | I12: 95 | J12: 63 | K12: none | L12: =services_weekly[[#This Row],[patients_admitted]]/services_weekly[[#This Row],[available_beds]] -> 1
B13: 3 | C13: 1 | D13: ICU | E13: 20 | F13: 21 | G13: 20 | H13: 1 | I13: 82 | J13: 89 | K13: none | L13: =services_weekly[[#This Row],[patients_admitted]]/services_weekly[[#This Row],[available_beds]] -> 1
... B209: 52 | C209: 12 | D209: ICU | E209: 22 | F209: 24 | G209: 22 | H209: 2 | I209: 80 | J209: 96 | K209: none | L209: =services_weekly[[#This Row],[patients_admitted]]/services_weekly[[#This Row],[available_beds]] -> 1

Sheet patients
B1: patient_id | C1: name | D1: age | E1: arrival_date | F1: departure_date | G1: service | H1: satisfaction | I1: length_of_stay | J1: age_group | K1: month_name (when arrived) | L1: month_number | M1: over_average_stay_or_not | N1: Average_length_of_stay
B2: PAT-09484753 | C2: Richard Rodriguez | D2: 24 | E2: 45732 | F2: 45738 | G2: surgery | H2: 61 | I2: =patients[[#This Row],[departure_date]]-patients[[#This Row],[arrival_date]] -> 6 | J2: =IF(patients[[#This Row],[age]] < 18,"0-17",IF(patients[[#This Row],[age]] < 40,"18-39",IF(patients[[#This Row],[age]] < 65,"40-64","65+"))) -> 18-39 | K2: =TEXT(patients[[#This Row],[arrival_date]],"[$-409]mmmm") -> March | L2: =MATCH(K2, {"January";"February";"March";"April";"May";"June";"July";"August";"September";"October";"November";"December"}, 0) -> 3 | M2: {=IF(patients[[#This Row],[length_of_stay]]>patients!$N$2:$N$2,"Over average","Less than average")} -> Less than average | N2: =AVERAGE(patients[length_of_stay]) -> 7.407
B3: PAT-f0644084 | C3: Shannon Walker | D3: 6 | E3: 46004 | F3: 46005 | G3: surgery | H3: 83 | I3: =patients[[#This Row],[departure_date]]-patients[[#This Row],[arrival_date]] -> 1 | J3: =IF(patients[[#This Row],[age]] < 18,"0-17",IF(patients[[#This Row],[age]] < 40,"18-39",IF(patients[[#This Row],[age]] < 65,"40-64","65+"))) -> 0-17 | K3: =TEXT(patients[[#This Row],[arrival_date]],"[$-409]mmmm") -> December | L3: =MATCH(K3, {"January";"February";"March";"April";"May";"June";"July";"August";"September";"October";"November";"December"}, 0) -> 12 | M3: {=IF(patients[[#This Row],[length_of_stay]]>patients!$N$2:$N$2,"Over average","Less than average")} -> Less than average
B4: PAT-ac6162e4 | C4: Julia Torres | D4: 24 | E4: 45837 | F4: 45843 | G4: general_medicine | H4: 83 | I4: =patients[[#This Row],[departure_date]]-patients[[#This Row],[arrival_date]] -> 6 | J4: =IF(patients[[#This Row],[age]] < 18,"0-17",IF(patients[[#This Row],[age]] < 40,"18-39",IF(patients[[#This Row],[age]] < 65,"40-64","65+"))) -> 18-39 | K4: =TEXT(patients[[#This Row],[arrival_date]],"[$-409]mmmm") -> June | L4: =MATCH(K4, {"January";"February";"March";"April";"May";"June";"July";"August";"September";"October";"November";"December"}, 0) -> 6 | M4: {=IF(patients[[#This Row],[length_of_stay]]>patients!$N$2:$N$2,"Over average","Less than average")} -> Less than average
B5: PAT-3dda2bb5 | C5: Crystal Johnson | D5: 32 | E5: 45942 | F5: 45953 | G5: emergency | H5: 81 | I5: =patients[[#This Row],[departure_date]]-patients[[#This Row],[arrival_date]] -> 11 | J5: =IF(patients[[#This Row],[age]] < 18,"0-17",IF(patients[[#This Row],[age]] < 40,"18-39",IF(patients[[#This Row],[age]] < 65,"40-64","65+"))) -> 18-39 | K5: =TEXT(patients[[#This Row],[arrival_date]],"[$-409]mmmm") -> October | L5: =MATCH(K5, {"January";"February";"March";"April";"May";"June";"July";"August";"September";"October";"November";"December"}, 0) -> 10 | M5: {=IF(patients[[#This Row],[length_of_stay]]>patients!$N$2:$N$2,"Over average","Less than average")} -> Over average
B6: PAT-08591375 | C6: Garrett Lin | D6: 25 | E6: 45706 | F6: 45713 | G6: ICU | H6: 76 | I6: =patients[[#This Row],[departure_date]]-patients[[#This Row],[arrival_date]] -> 7 | J6: =IF(patients[[#This Row],[age]] < 18,"0-17",IF(patients[[#This Row],[age]] < 40,"18-39",IF(patients[[#This Row],[age]] < 65,"40-64","65+"))) -> 18-39 | K6: =TEXT(patients[[#This Row],[arrival_date]],"[$-409]mmmm") -> February | L6: =MATCH(K6, {"January";"February";"March";"April";"May";"June";"July";"August";"September";"October";"November";"December"}, 0) -> 2 | M6: {=IF(patients[[#This Row],[length_of_stay]]>patients!$N$2:$N$2,"Over average","Less than average")} -> Less than average
B7: PAT-f4b29bae | C7: Diana May | D7: 83 | E7: 45834 | F7: 45838 | G7: emergency | H7: 81 | I7: =patients[[#This Row],[departure_date]]-patients[[#This Row],[arrival_date]] -> 4 | J7: =IF(patients[[#This Row],[age]] < 18,"0-17",IF(patients[[#This Row],[age]] < 40,"18-39",IF(patients[[#This Row],[age]] < 65,"40-64","65+"))) -> 65+ | K7: =TEXT(patients[[#This Row],[arrival_date]],"[$-409]mmmm") -> June | L7: =MATCH(K7, {"January";"February";"March";"April";"May";"June";"July";"August";"September";"October";"November";"December"}, 0) -> 6 | M7: {=IF(patients[[#This Row],[length_of_stay]]>patients!$N$2:$N$2,"Over average","Less than average")} -> Less than average
B8: PAT-283cda07 | C8: William Herrera | D8: 62 | E8: 46017 | F8: 46018 | G8: emergency | H8: 66 | I8: =patients[[#This Row],[departure_date]]-patients[[#This Row],[arrival_date]] -> 1 | J8: =IF(patients[[#This Row],[age]] < 18,"0-17",IF(patients[[#This Row],[age]] < 40,"18-39",IF(patients[[#This Row],[age]] < 65,"40-64","65+"))) -> 40-64 | K8: =TEXT(patients[[#This Row],[arrival_date]],"[$-409]mmmm") -> December | L8: =MATCH(K8, {"January";"February";"March";"April";"May";"June";"July";"August";"September";"October";"November";"December"}, 0) -> 12 | M8: {=IF(patients[[#This Row],[length_of_stay]]>patients!$N$2:$N$2,"Over average","Less than average")} -> Less than average
B9: PAT-5b61868c | C9: Ashley Waller | D9: 0 | E9: 45798 | F9: 45812 | G9: ICU | H9: 82 | I9: =patients[[#This Row],[departure_date]]-patients[[#This Row],[arrival_date]] -> 14 | J9: =IF(patients[[#This Row],[age]] < 18,"0-17",IF(patients[[#This Row],[age]] < 40,"18-39",IF(patients[[#This Row],[age]] < 65,"40-64","65+"))) -> 0-17 | K9: =TEXT(patients[[#This Row],[arrival_date]],"[$-409]mmmm") -> May | L9: =MATCH(K9, {"January";"February";"March";"April";"May";"June";"July";"August";"September";"October";"November";"December"}, 0) -> 5 | M9: {=IF(patients[[#This Row],[length_of_stay]]>patients!$N$2:$N$2,"Over average","Less than average")} -> Over average
B10: PAT-f9c8afa6 | C10: Victor Baker | D10: 50 | E10: 45868 | F10: 45882 | G10: general_medicine | H10: 91 | I10: =patients[[#This Row],[departure_date]]-patients[[#This Row],[arrival_date]] -> 14 | J10: =IF(patients[[#This Row],[age]] < 18,"0-17",IF(patients[[#This Row],[age]] < 40,"18-39",IF(patients[[#This Row],[age]] < 65,"40-64","65+"))) -> 40-64 | K10: =TEXT(patients[[#This Row],[arrival_date]],"[$-409]mmmm") -> July | L10: =MATCH(K10, {"January";"February";"March";"April";"May";"June";"July";"August";"September";"October";"November";"December"}, 0) -> 7 | M10: {=IF(patients[[#This Row],[length_of_stay]]>patients!$N$2:$N$2,"Over average","Less than average")} -> Over average
B11: PAT-5290be70 | C11: Jeffrey Chandler | D11: 29 | E11: 45962 | F11: 45975 | G11: emergency | H11: 88 | I11: =patients[[#This Row],[departure_date]]-patients[[#This Row],[arrival_date]] -> 13 | J11: =IF(patients[[#This Row],[age]] < 18,"0-17",IF(patients[[#This Row],[age]] < 40,"18-39",IF(patients[[#This Row],[age]] < 65,"40-64","65+"))) -> 18-39 | K11: =TEXT(patients[[#This Row],[arrival_date]],"[$-409]mmmm") -> November | L11: =MATCH(K11, {"January";"February";"March";"April";"May";"June";"July";"August";"September";"October";"November";"December"}, 0) -> 11 | M11: {=IF(patients[[#This Row],[length_of_stay]]>patients!$N$2:$N$2,"Over average","Less than average")} -> Over average
B12: PAT-003ce690 | C12: Larry Dixon | D12: 29 | E12: 45676 | F12: 45678 | G12: ICU | H12: 60 | I12: =patients[[#This Row],[departure_date]]-patients[[#This Row],[arrival_date]] -> 2 | J12: =IF(patients[[#This Row],[age]] < 18,"0-17",IF(patients[[#This Row],[age]] < 40,"18-39",IF(patients[[#This Row],[age]] < 65,"40-64","65+"))) -> 18-39 | K12: =TEXT(patients[[#This Row],[arrival_date]],"[$-409]mmmm") -> January | L12: =MATCH(K12, {"January";"February";"March";"April";"May";"June";"July";"August";"September";"October";"November";"December"}, 0) -> 1 | M12: {=IF(patients[[#This Row],[length_of_stay]]>patients!$N$2:$N$2,"Over average","Less than average")} -> Less than average
B13: PAT-18f78014 | C13: Kenneth Scott | D13: 77 | E13: 45832 | F13: 45834 | G13: general_medicine | H13: 61 | I13: =patients[[#This Row],[departure_date]]-patients[[#This Row],[arrival_date]] -> 2 | J13: =IF(patients[[#This Row],[age]] < 18,"0-17",IF(patients[[#This Row],[age]] < 40,"18-39",IF(patients[[#This Row],[age]] < 65,"40-64","65+"))) -> 65+ | K13: =TEXT(patients[[#This Row],[arrival_date]],"[$-409]mmmm") -> June | L13: =MATCH(K13, {"January";"February";"March";"April";"May";"June";"July";"August";"September";"October";"November";"December"}, 0) -> 6 | M13: {=IF(patients[[#This Row],[length_of_stay]]>patients!$N$2:$N$2,"Over average","Less than average")} -> Less than average
B14: PAT-69dc0dc1 | C14: April Frost | D14: 37 | E14: 45976 | F14: 45980 | G14: general_medicine | H14: 60 | I14: =patients[[#This Row],[departure_date]]-patients[[#This Row],[arrival_date]] -> 4 | J14: =IF(patients[[#This Row],[age]] < 18,"0-17",IF(patients[[#This Row],[age]] < 40,"18-39",IF(patients[[#This Row],[age]] < 65,"40-64","65+"))) -> 18-39 | K14: =TEXT(patients[[#This Row],[arrival_date]],"[$-409]mmmm") -> November | L14: =MATCH(K14, {"January";"February";"March";"April";"May";"June";"July";"August";"September";"October";"November";"December"}, 0) -> 11 | M14: {=IF(patients[[#This Row],[length_of_stay]]>patients!$N$2:$N$2,"Over average","Less than average")} -> Less than average
... B1001: PAT-e2ef9c5f | C1001: Lorraine Turner | D1001: 64 | E1001: 45781 | F1001: 45785 | G1001: general_medicine | H1001: 83 | I1001: =patients[[#This Row],[departure_date]]-patients[[#This Row],[arrival_date]] -> 4 | J1001: =IF(patients[[#This Row],[age]] < 18,"0-17",IF(patients[[#This Row],[age]] < 40,"18-39",IF(patients[[#This Row],[age]] < 65,"40-64","65+"))) -> 40-64 | K1001: =TEXT(patients[[#This Row],[arrival_date]],"[$-409]mmmm") -> May | L1001: =MATCH(K1001, {"January";"February";"March";"April";"May";"June";"July";"August";"September";"October";"November";"December"}, 0) -> 5 | M1001: {=IF(patients[[#This Row],[length_of_stay]]>patients!$N$2:$N$2,"Over average","Less than average")} -> Less than average

Sheet raw_calculations
D3: Row Labels | E3: Count of patient_id | H3: =AVERAGE(patients[length_of_stay]) -> 7.407 | I3: =ROWS(patients[patient_id]) / COUNTIFS(staff[[#All],[role]],"doctor") -> 55.555556
D4: emergency | E4: 263
D5: general_medicine | E5: 242
D6: ICU | E6: 241 | J6: Row Labels | K6: Count of patient_id
D7: surgery | E7: 254 | J7: 1 | K7: 85
D8: Grand Total | E8: 1000 | J8: 2 | K8: 80
J9: 3 | K9: 75
J10: 4 | K10: 81
J11: 5 | K11: 85
J12: 6 | K12: 81 | N12: =1000/110 -> 9.0909091
J13: 7 | K13: 82
J14: 8 | K14: 88
C15: Count of patient_id | D15: Column Labels | J15: 9 | K15: 94
C16: Row Labels | D16: emergency | E16: general_medicine | F16: ICU | G16: surgery | H16: Grand Total | J16: 10 | K16: 92
C17: 0-17 | D17: 53 | E17: 39 | F17: 37 | G17: 56 | H17: 185 | J17: 11 | K17: 83
C18: 18-39 | D18: 58 | E18: 60 | F18: 78 | G18: 53 | H18: 249 | J18: 12 | K18: 74
C19: 40-64 | D19: 79 | E19: 74 | F19: 59 | G19: 67 | H19: 279
C20: 65+ | D20: 73 | E20: 69 | F20: 67 | G20: 78 | H20: 287
C21: Grand Total | D21: 263 | E21: 242 | F21: 241 | G21: 254 | H21: 1000
J23: Row Labels | K23: Average of patient_satisfaction
J24: emergency | K24: 77.884615
D25: Row Labels | E25: Average of % of bed occupancy | J25: general_medicine | K25: 81.230769
D26: 1 | E26: 0.94296875 | J26: ICU | K26: 81.615385
D27: 2 | E27: 0.91709638 | J27: surgery | K27: 79.269231
D28: 3 | E28: 0.94121647 | J28: Grand Total | K28: 80
D29: 4 | E29: 0.93770346
D30: 5 | E30: 0.93554131
D31: 6 | E31: 0.9027262
D32: 7 | E32: 0.89708224 | I32: =AVERAGE(patients[age]) -> 45.337
D33: 8 | E33: 0.93820705
D34: 9 | E34: 0.87720678 | K34: Row Labels | L34: Average of satisfaction
D35: 10 | E35: 0.96938718 | K35: 1 | L35: 78.539474
D36: 11 | E36: 0.91570437 | K36: 2 | L36: 77.318182
D37: 12 | E37: 0.92316083 | K37: 3 | L37: 78.264706
D38: Grand Total | E38: 0.92470476 | K38: 4 | L38: 78.791667
K39: 5 | L39: 79.941176
K40: 6 | L40: 80.317073
K41: 7 | L41: 78.727273
K42: 8 | L42: 78.72
K43: 9 | L43: 80.455696
...

Sheet dashboard

Sheet specific_info
